2020-05-22 10:57:21,55 INFO     [autoreload.py:222] /home/sravya/SPEW/BackenedAfterIntegrationwithAWS/SCPapp/views.py changed, reloading.
2020-05-22 10:58:06 INFO     [autoreload.py:222] /home/sravya/SPEW/BackenedAfterIntegrationwithAWS/SCPapp/views.py changed, reloading.
2020-05-22 11:07:08,784 INFO     [views.py:43] Trying: GET: User data by rollNumber MT2019114
2020-05-22 11:07:13,757 INFO     [views.py:53] Successful: GET: User data by rollNumber MT2019114
2020-05-22 11:17:09,139 INFO     [views.py:68] Trying: GET: Interview Exp Data
2020-05-22 11:17:09,327 INFO     [views.py:71] Successful: GET: Interview Exp Data
2020-05-22 11:17:22,649 ERROR    [log.py:228] Internal Server Error: /interviewData/
Traceback (most recent call last):
  File "/home/sravya/.local/lib/python3.6/site-packages/django/db/backends/utils.py", line 86, in _execute
    return self.cursor.execute(sql, params)
psycopg2.errors.UndefinedColumn: column SCPapp_interview.created does not exist
LINE 1: ...."company", "SCPapp_interview"."numberofUpvotes", "SCPapp_in...
                                                             ^


The above exception was the direct cause of the following exception:

Traceback (most recent call last):
  File "/home/sravya/.local/lib/python3.6/site-packages/django/core/handlers/exception.py", line 34, in inner
    response = get_response(request)
  File "/home/sravya/.local/lib/python3.6/site-packages/django/core/handlers/base.py", line 115, in _get_response
    response = self.process_exception_by_middleware(e, request)
  File "/home/sravya/.local/lib/python3.6/site-packages/django/core/handlers/base.py", line 113, in _get_response
    response = wrapped_callback(request, *callback_args, **callback_kwargs)
  File "/home/sravya/.local/lib/python3.6/site-packages/django/views/decorators/csrf.py", line 54, in wrapped_view
    return view_func(*args, **kwargs)
  File "/home/sravya/.local/lib/python3.6/site-packages/django/views/generic/base.py", line 71, in view
    return self.dispatch(request, *args, **kwargs)
  File "/usr/local/lib/python3.6/dist-packages/rest_framework/views.py", line 505, in dispatch
    response = self.handle_exception(exc)
  File "/usr/local/lib/python3.6/dist-packages/rest_framework/views.py", line 465, in handle_exception
    self.raise_uncaught_exception(exc)
  File "/usr/local/lib/python3.6/dist-packages/rest_framework/views.py", line 476, in raise_uncaught_exception
    raise exc
  File "/usr/local/lib/python3.6/dist-packages/rest_framework/views.py", line 502, in dispatch
    response = handler(request, *args, **kwargs)
  File "/home/sravya/SPEW/BackenedAfterIntegrationwithAWS/SCPapp/views.py", line 72, in get
    return Response(serializer.data)
  File "/usr/local/lib/python3.6/dist-packages/rest_framework/serializers.py", line 760, in data
    ret = super().data
  File "/usr/local/lib/python3.6/dist-packages/rest_framework/serializers.py", line 260, in data
    self._data = self.to_representation(self.instance)
  File "/usr/local/lib/python3.6/dist-packages/rest_framework/serializers.py", line 678, in to_representation
    self.child.to_representation(item) for item in iterable
  File "/home/sravya/.local/lib/python3.6/site-packages/django/db/models/query.py", line 276, in __iter__
    self._fetch_all()
  File "/home/sravya/.local/lib/python3.6/site-packages/django/db/models/query.py", line 1261, in _fetch_all
    self._result_cache = list(self._iterable_class(self))
  File "/home/sravya/.local/lib/python3.6/site-packages/django/db/models/query.py", line 57, in __iter__
    results = compiler.execute_sql(chunked_fetch=self.chunked_fetch, chunk_size=self.chunk_size)
  File "/home/sravya/.local/lib/python3.6/site-packages/django/db/models/sql/compiler.py", line 1151, in execute_sql
    cursor.execute(sql, params)
  File "/home/sravya/.local/lib/python3.6/site-packages/django/db/backends/utils.py", line 100, in execute
    return super().execute(sql, params)
  File "/home/sravya/.local/lib/python3.6/site-packages/django/db/backends/utils.py", line 68, in execute
    return self._execute_with_wrappers(sql, params, many=False, executor=self._execute)
  File "/home/sravya/.local/lib/python3.6/site-packages/django/db/backends/utils.py", line 77, in _execute_with_wrappers
    return executor(sql, params, many, context)
  File "/home/sravya/.local/lib/python3.6/site-packages/django/db/backends/utils.py", line 86, in _execute
    return self.cursor.execute(sql, params)
  File "/home/sravya/.local/lib/python3.6/site-packages/django/db/utils.py", line 90, in __exit__
    raise dj_exc_value.with_traceback(traceback) from exc_value
  File "/home/sravya/.local/lib/python3.6/site-packages/django/db/backends/utils.py", line 86, in _execute
    return self.cursor.execute(sql, params)
django.db.utils.ProgrammingError: column SCPapp_interview.created does not exist
LINE 1: ...."company", "SCPapp_interview"."numberofUpvotes", "SCPapp_in...
                                                             ^

2020-05-22 11:30:30,344 INFO     [views.py:68] Trying: GET: Interview Exp Data
2020-05-22 11:30:30,376 INFO     [views.py:71] Successful: GET: Interview Exp Data
2020-05-22 11:30:48,52 ERROR    [log.py:228] Internal Server Error: /interviewData/
Traceback (most recent call last):
  File "/home/sravya/.local/lib/python3.6/site-packages/django/db/backends/utils.py", line 86, in _execute
    return self.cursor.execute(sql, params)
psycopg2.errors.UndefinedColumn: column SCPapp_interview.created does not exist
LINE 1: ...."company", "SCPapp_interview"."numberofUpvotes", "SCPapp_in...
                                                             ^


The above exception was the direct cause of the following exception:

Traceback (most recent call last):
  File "/home/sravya/.local/lib/python3.6/site-packages/django/core/handlers/exception.py", line 34, in inner
    response = get_response(request)
  File "/home/sravya/.local/lib/python3.6/site-packages/django/core/handlers/base.py", line 115, in _get_response
    response = self.process_exception_by_middleware(e, request)
  File "/home/sravya/.local/lib/python3.6/site-packages/django/core/handlers/base.py", line 113, in _get_response
    response = wrapped_callback(request, *callback_args, **callback_kwargs)
  File "/home/sravya/.local/lib/python3.6/site-packages/django/views/decorators/csrf.py", line 54, in wrapped_view
    return view_func(*args, **kwargs)
  File "/home/sravya/.local/lib/python3.6/site-packages/django/views/generic/base.py", line 71, in view
    return self.dispatch(request, *args, **kwargs)
  File "/usr/local/lib/python3.6/dist-packages/rest_framework/views.py", line 505, in dispatch
    response = self.handle_exception(exc)
  File "/usr/local/lib/python3.6/dist-packages/rest_framework/views.py", line 465, in handle_exception
    self.raise_uncaught_exception(exc)
  File "/usr/local/lib/python3.6/dist-packages/rest_framework/views.py", line 476, in raise_uncaught_exception
    raise exc
  File "/usr/local/lib/python3.6/dist-packages/rest_framework/views.py", line 502, in dispatch
    response = handler(request, *args, **kwargs)
  File "/home/sravya/SPEW/BackenedAfterIntegrationwithAWS/SCPapp/views.py", line 72, in get
    return Response(serializer.data)
  File "/usr/local/lib/python3.6/dist-packages/rest_framework/serializers.py", line 760, in data
    ret = super().data
  File "/usr/local/lib/python3.6/dist-packages/rest_framework/serializers.py", line 260, in data
    self._data = self.to_representation(self.instance)
  File "/usr/local/lib/python3.6/dist-packages/rest_framework/serializers.py", line 678, in to_representation
    self.child.to_representation(item) for item in iterable
  File "/home/sravya/.local/lib/python3.6/site-packages/django/db/models/query.py", line 276, in __iter__
    self._fetch_all()
  File "/home/sravya/.local/lib/python3.6/site-packages/django/db/models/query.py", line 1261, in _fetch_all
    self._result_cache = list(self._iterable_class(self))
  File "/home/sravya/.local/lib/python3.6/site-packages/django/db/models/query.py", line 57, in __iter__
    results = compiler.execute_sql(chunked_fetch=self.chunked_fetch, chunk_size=self.chunk_size)
  File "/home/sravya/.local/lib/python3.6/site-packages/django/db/models/sql/compiler.py", line 1151, in execute_sql
    cursor.execute(sql, params)
  File "/home/sravya/.local/lib/python3.6/site-packages/django/db/backends/utils.py", line 100, in execute
    return super().execute(sql, params)
  File "/home/sravya/.local/lib/python3.6/site-packages/django/db/backends/utils.py", line 68, in execute
    return self._execute_with_wrappers(sql, params, many=False, executor=self._execute)
  File "/home/sravya/.local/lib/python3.6/site-packages/django/db/backends/utils.py", line 77, in _execute_with_wrappers
    return executor(sql, params, many, context)
  File "/home/sravya/.local/lib/python3.6/site-packages/django/db/backends/utils.py", line 86, in _execute
    return self.cursor.execute(sql, params)
  File "/home/sravya/.local/lib/python3.6/site-packages/django/db/utils.py", line 90, in __exit__
    raise dj_exc_value.with_traceback(traceback) from exc_value
  File "/home/sravya/.local/lib/python3.6/site-packages/django/db/backends/utils.py", line 86, in _execute
    return self.cursor.execute(sql, params)
django.db.utils.ProgrammingError: column SCPapp_interview.created does not exist
LINE 1: ...."company", "SCPapp_interview"."numberofUpvotes", "SCPapp_in...
                                                             ^

2020-05-22 11:30:51,707 WARNING  [log.py:228] Not Found: /favicon.ico
2020-05-22 11:36:42,220 INFO     [views.py:135] Trying: GET: PYQ Data
2020-05-22 11:36:42,220 INFO     [views.py:152] Successful: GET: PYQ Data
2020-05-22 11:36:59,118 ERROR    [log.py:228] Internal Server Error: /getData/
Traceback (most recent call last):
  File "/home/sravya/.local/lib/python3.6/site-packages/django/db/backends/utils.py", line 86, in _execute
    return self.cursor.execute(sql, params)
psycopg2.errors.UndefinedColumn: column SCPapp_file.created does not exist
LINE 1: ...berofUpvotes", "SCPapp_file"."numberofDownvotes", "SCPapp_fi...
                                                             ^


The above exception was the direct cause of the following exception:

Traceback (most recent call last):
  File "/home/sravya/.local/lib/python3.6/site-packages/django/core/handlers/exception.py", line 34, in inner
    response = get_response(request)
  File "/home/sravya/.local/lib/python3.6/site-packages/django/core/handlers/base.py", line 115, in _get_response
    response = self.process_exception_by_middleware(e, request)
  File "/home/sravya/.local/lib/python3.6/site-packages/django/core/handlers/base.py", line 113, in _get_response
    response = wrapped_callback(request, *callback_args, **callback_kwargs)
  File "/home/sravya/.local/lib/python3.6/site-packages/django/views/decorators/csrf.py", line 54, in wrapped_view
    return view_func(*args, **kwargs)
  File "/home/sravya/.local/lib/python3.6/site-packages/django/views/generic/base.py", line 71, in view
    return self.dispatch(request, *args, **kwargs)
  File "/usr/local/lib/python3.6/dist-packages/rest_framework/views.py", line 505, in dispatch
    response = self.handle_exception(exc)
  File "/usr/local/lib/python3.6/dist-packages/rest_framework/views.py", line 465, in handle_exception
    self.raise_uncaught_exception(exc)
  File "/usr/local/lib/python3.6/dist-packages/rest_framework/views.py", line 476, in raise_uncaught_exception
    raise exc
  File "/usr/local/lib/python3.6/dist-packages/rest_framework/views.py", line 502, in dispatch
    response = handler(request, *args, **kwargs)
  File "/home/sravya/SPEW/BackenedAfterIntegrationwithAWS/SCPapp/views.py", line 153, in get
    return Response(serializer.data)
  File "/usr/local/lib/python3.6/dist-packages/rest_framework/serializers.py", line 760, in data
    ret = super().data
  File "/usr/local/lib/python3.6/dist-packages/rest_framework/serializers.py", line 260, in data
    self._data = self.to_representation(self.instance)
  File "/usr/local/lib/python3.6/dist-packages/rest_framework/serializers.py", line 678, in to_representation
    self.child.to_representation(item) for item in iterable
  File "/home/sravya/.local/lib/python3.6/site-packages/django/db/models/query.py", line 276, in __iter__
    self._fetch_all()
  File "/home/sravya/.local/lib/python3.6/site-packages/django/db/models/query.py", line 1261, in _fetch_all
    self._result_cache = list(self._iterable_class(self))
  File "/home/sravya/.local/lib/python3.6/site-packages/django/db/models/query.py", line 57, in __iter__
    results = compiler.execute_sql(chunked_fetch=self.chunked_fetch, chunk_size=self.chunk_size)
  File "/home/sravya/.local/lib/python3.6/site-packages/django/db/models/sql/compiler.py", line 1151, in execute_sql
    cursor.execute(sql, params)
  File "/home/sravya/.local/lib/python3.6/site-packages/django/db/backends/utils.py", line 100, in execute
    return super().execute(sql, params)
  File "/home/sravya/.local/lib/python3.6/site-packages/django/db/backends/utils.py", line 68, in execute
    return self._execute_with_wrappers(sql, params, many=False, executor=self._execute)
  File "/home/sravya/.local/lib/python3.6/site-packages/django/db/backends/utils.py", line 77, in _execute_with_wrappers
    return executor(sql, params, many, context)
  File "/home/sravya/.local/lib/python3.6/site-packages/django/db/backends/utils.py", line 86, in _execute
    return self.cursor.execute(sql, params)
  File "/home/sravya/.local/lib/python3.6/site-packages/django/db/utils.py", line 90, in __exit__
    raise dj_exc_value.with_traceback(traceback) from exc_value
  File "/home/sravya/.local/lib/python3.6/site-packages/django/db/backends/utils.py", line 86, in _execute
    return self.cursor.execute(sql, params)
django.db.utils.ProgrammingError: column SCPapp_file.created does not exist
LINE 1: ...berofUpvotes", "SCPapp_file"."numberofDownvotes", "SCPapp_fi...
                                                             ^

2020-05-22 11:51:22,835 ERROR    [log.py:228] Internal Server Error: /admin/SCPapp/interview/
Traceback (most recent call last):
  File "/home/sravya/.local/lib/python3.6/site-packages/django/db/backends/utils.py", line 86, in _execute
    return self.cursor.execute(sql, params)
psycopg2.errors.UndefinedColumn: column SCPapp_interview.created does not exist
LINE 1: ...."company", "SCPapp_interview"."numberofUpvotes", "SCPapp_in...
                                                             ^


The above exception was the direct cause of the following exception:

Traceback (most recent call last):
  File "/home/sravya/.local/lib/python3.6/site-packages/django/core/handlers/exception.py", line 34, in inner
    response = get_response(request)
  File "/home/sravya/.local/lib/python3.6/site-packages/django/core/handlers/base.py", line 115, in _get_response
    response = self.process_exception_by_middleware(e, request)
  File "/home/sravya/.local/lib/python3.6/site-packages/django/core/handlers/base.py", line 113, in _get_response
    response = wrapped_callback(request, *callback_args, **callback_kwargs)
  File "/home/sravya/.local/lib/python3.6/site-packages/django/contrib/admin/options.py", line 607, in wrapper
    return self.admin_site.admin_view(view)(*args, **kwargs)
  File "/home/sravya/.local/lib/python3.6/site-packages/django/utils/decorators.py", line 130, in _wrapped_view
    response = view_func(request, *args, **kwargs)
  File "/home/sravya/.local/lib/python3.6/site-packages/django/views/decorators/cache.py", line 44, in _wrapped_view_func
    response = view_func(request, *args, **kwargs)
  File "/home/sravya/.local/lib/python3.6/site-packages/django/contrib/admin/sites.py", line 231, in inner
    return view(request, *args, **kwargs)
  File "/home/sravya/.local/lib/python3.6/site-packages/django/utils/decorators.py", line 43, in _wrapper
    return bound_method(*args, **kwargs)
  File "/home/sravya/.local/lib/python3.6/site-packages/django/utils/decorators.py", line 130, in _wrapped_view
    response = view_func(request, *args, **kwargs)
  File "/home/sravya/.local/lib/python3.6/site-packages/django/contrib/admin/options.py", line 1796, in changelist_view
    'selection_note': _('0 of %(cnt)s selected') % {'cnt': len(cl.result_list)},
  File "/home/sravya/.local/lib/python3.6/site-packages/django/db/models/query.py", line 258, in __len__
    self._fetch_all()
  File "/home/sravya/.local/lib/python3.6/site-packages/django/db/models/query.py", line 1261, in _fetch_all
    self._result_cache = list(self._iterable_class(self))
  File "/home/sravya/.local/lib/python3.6/site-packages/django/db/models/query.py", line 57, in __iter__
    results = compiler.execute_sql(chunked_fetch=self.chunked_fetch, chunk_size=self.chunk_size)
  File "/home/sravya/.local/lib/python3.6/site-packages/django/db/models/sql/compiler.py", line 1151, in execute_sql
    cursor.execute(sql, params)
  File "/home/sravya/.local/lib/python3.6/site-packages/django/db/backends/utils.py", line 100, in execute
    return super().execute(sql, params)
  File "/home/sravya/.local/lib/python3.6/site-packages/django/db/backends/utils.py", line 68, in execute
    return self._execute_with_wrappers(sql, params, many=False, executor=self._execute)
  File "/home/sravya/.local/lib/python3.6/site-packages/django/db/backends/utils.py", line 77, in _execute_with_wrappers
    return executor(sql, params, many, context)
  File "/home/sravya/.local/lib/python3.6/site-packages/django/db/backends/utils.py", line 86, in _execute
    return self.cursor.execute(sql, params)
  File "/home/sravya/.local/lib/python3.6/site-packages/django/db/utils.py", line 90, in __exit__
    raise dj_exc_value.with_traceback(traceback) from exc_value
  File "/home/sravya/.local/lib/python3.6/site-packages/django/db/backends/utils.py", line 86, in _execute
    return self.cursor.execute(sql, params)
django.db.utils.ProgrammingError: column SCPapp_interview.created does not exist
LINE 1: ...."company", "SCPapp_interview"."numberofUpvotes", "SCPapp_in...
                                                             ^
2020-05-22 11:07:08,784 INFO     [views.py:43] Trying: GET: User data by rollNumber MT2019114

2020-05-22 13:32:35,942 INFO     [views.py:135] Trying: GET: PYQ Data
2020-05-22 13:32:36,1 INFO     [views.py:152] Successful: GET: PYQ Data
2020-05-22 13:32:39,416 INFO     [views.py:135] Trying: GET: PYQ Data
2020-05-22 13:32:39,416 INFO     [views.py:152] Successful: GET: PYQ Data
2020-05-22 13:32:44,741 ERROR    [log.py:228] Internal Server Error: /getData/
Traceback (most recent call last):
  File "/home/sravya/.local/lib/python3.6/site-packages/django/db/backends/utils.py", line 86, in _execute
    return self.cursor.execute(sql, params)
psycopg2.errors.UndefinedColumn: column SCPapp_file.created does not exist
LINE 1: ...berofUpvotes", "SCPapp_file"."numberofDownvotes", "SCPapp_fi...
                                                             ^


The above exception was the direct cause of the following exception:

Traceback (most recent call last):
  File "/home/sravya/.local/lib/python3.6/site-packages/django/core/handlers/exception.py", line 34, in inner
    response = get_response(request)
  File "/home/sravya/.local/lib/python3.6/site-packages/django/core/handlers/base.py", line 115, in _get_response
    response = self.process_exception_by_middleware(e, request)
  File "/home/sravya/.local/lib/python3.6/site-packages/django/core/handlers/base.py", line 113, in _get_response
    response = wrapped_callback(request, *callback_args, **callback_kwargs)
  File "/home/sravya/.local/lib/python3.6/site-packages/django/views/decorators/csrf.py", line 54, in wrapped_view
    return view_func(*args, **kwargs)
  File "/home/sravya/.local/lib/python3.6/site-packages/django/views/generic/base.py", line 71, in view
    return self.dispatch(request, *args, **kwargs)
  File "/usr/local/lib/python3.6/dist-packages/rest_framework/views.py", line 505, in dispatch
    response = self.handle_exception(exc)
  File "/usr/local/lib/python3.6/dist-packages/rest_framework/views.py", line 465, in handle_exception
    self.raise_uncaught_exception(exc)
  File "/usr/local/lib/python3.6/dist-packages/rest_framework/views.py", line 476, in raise_uncaught_exception
    raise exc
  File "/usr/local/lib/python3.6/dist-packages/rest_framework/views.py", line 502, in dispatch
    response = handler(request, *args, **kwargs)
  File "/home/sravya/SPEW/BackenedAfterIntegrationwithAWS/SCPapp/views.py", line 153, in get
    return Response(serializer.data)
  File "/usr/local/lib/python3.6/dist-packages/rest_framework/serializers.py", line 760, in data
    ret = super().data
  File "/usr/local/lib/python3.6/dist-packages/rest_framework/serializers.py", line 260, in data
    self._data = self.to_representation(self.instance)
  File "/usr/local/lib/python3.6/dist-packages/rest_framework/serializers.py", line 678, in to_representation
    self.child.to_representation(item) for item in iterable
  File "/home/sravya/.local/lib/python3.6/site-packages/django/db/models/query.py", line 276, in __iter__
    self._fetch_all()
  File "/home/sravya/.local/lib/python3.6/site-packages/django/db/models/query.py", line 1261, in _fetch_all
    self._result_cache = list(self._iterable_class(self))
  File "/home/sravya/.local/lib/python3.6/site-packages/django/db/models/query.py", line 57, in __iter__
    results = compiler.execute_sql(chunked_fetch=self.chunked_fetch, chunk_size=self.chunk_size)
  File "/home/sravya/.local/lib/python3.6/site-packages/django/db/models/sql/compiler.py", line 1151, in execute_sql
    cursor.execute(sql, params)
  File "/home/sravya/.local/lib/python3.6/site-packages/django/db/backends/utils.py", line 100, in execute
    return super().execute(sql, params)
  File "/home/sravya/.local/lib/python3.6/site-packages/django/db/backends/utils.py", line 68, in execute
    return self._execute_with_wrappers(sql, params, many=False, executor=self._execute)
  File "/home/sravya/.local/lib/python3.6/site-packages/django/db/backends/utils.py", line 77, in _execute_with_wrappers
    return executor(sql, params, many, context)
  File "/home/sravya/.local/lib/python3.6/site-packages/django/db/backends/utils.py", line 86, in _execute
    return self.cursor.execute(sql, params)
  File "/home/sravya/.local/lib/python3.6/site-packages/django/db/utils.py", line 90, in __exit__
    raise dj_exc_value.with_traceback(traceback) from exc_value
  File "/home/sravya/.local/lib/python3.6/site-packages/django/db/backends/utils.py", line 86, in _execute
    return self.cursor.execute(sql, params)
django.db.utils.ProgrammingError: column SCPapp_file.created does not exist
LINE 1: ...berofUpvotes", "SCPapp_file"."numberofDownvotes", "SCPapp_fi...
                                                             ^

2020-05-22 13:32:46,266 ERROR    [log.py:228] Internal Server Error: /getData/
Traceback (most recent call last):
  File "/home/sravya/.local/lib/python3.6/site-packages/django/db/backends/utils.py", line 86, in _execute
    return self.cursor.execute(sql, params)
psycopg2.errors.UndefinedColumn: column SCPapp_file.created does not exist
LINE 1: ...berofUpvotes", "SCPapp_file"."numberofDownvotes", "SCPapp_fi...
                                                             ^


The above exception was the direct cause of the following exception:

Traceback (most recent call last):
  File "/home/sravya/.local/lib/python3.6/site-packages/django/core/handlers/exception.py", line 34, in inner
    response = get_response(request)
  File "/home/sravya/.local/lib/python3.6/site-packages/django/core/handlers/base.py", line 115, in _get_response
    response = self.process_exception_by_middleware(e, request)
  File "/home/sravya/.local/lib/python3.6/site-packages/django/core/handlers/base.py", line 113, in _get_response
    response = wrapped_callback(request, *callback_args, **callback_kwargs)
  File "/home/sravya/.local/lib/python3.6/site-packages/django/views/decorators/csrf.py", line 54, in wrapped_view
    return view_func(*args, **kwargs)
  File "/home/sravya/.local/lib/python3.6/site-packages/django/views/generic/base.py", line 71, in view
    return self.dispatch(request, *args, **kwargs)
  File "/usr/local/lib/python3.6/dist-packages/rest_framework/views.py", line 505, in dispatch
    response = self.handle_exception(exc)
  File "/usr/local/lib/python3.6/dist-packages/rest_framework/views.py", line 465, in handle_exception
    self.raise_uncaught_exception(exc)
  File "/usr/local/lib/python3.6/dist-packages/rest_framework/views.py", line 476, in raise_uncaught_exception
    raise exc
  File "/usr/local/lib/python3.6/dist-packages/rest_framework/views.py", line 502, in dispatch
    response = handler(request, *args, **kwargs)
  File "/home/sravya/SPEW/BackenedAfterIntegrationwithAWS/SCPapp/views.py", line 153, in get
    return Response(serializer.data)
  File "/usr/local/lib/python3.6/dist-packages/rest_framework/serializers.py", line 760, in data
    ret = super().data
  File "/usr/local/lib/python3.6/dist-packages/rest_framework/serializers.py", line 260, in data
    self._data = self.to_representation(self.instance)
  File "/usr/local/lib/python3.6/dist-packages/rest_framework/serializers.py", line 678, in to_representation
    self.child.to_representation(item) for item in iterable
  File "/home/sravya/.local/lib/python3.6/site-packages/django/db/models/query.py", line 276, in __iter__
    self._fetch_all()
  File "/home/sravya/.local/lib/python3.6/site-packages/django/db/models/query.py", line 1261, in _fetch_all
    self._result_cache = list(self._iterable_class(self))
  File "/home/sravya/.local/lib/python3.6/site-packages/django/db/models/query.py", line 57, in __iter__
    results = compiler.execute_sql(chunked_fetch=self.chunked_fetch, chunk_size=self.chunk_size)
  File "/home/sravya/.local/lib/python3.6/site-packages/django/db/models/sql/compiler.py", line 1151, in execute_sql
    cursor.execute(sql, params)
  File "/home/sravya/.local/lib/python3.6/site-packages/django/db/backends/utils.py", line 100, in execute
    return super().execute(sql, params)
  File "/home/sravya/.local/lib/python3.6/site-packages/django/db/backends/utils.py", line 68, in execute
    return self._execute_with_wrappers(sql, params, many=False, executor=self._execute)
  File "/home/sravya/.local/lib/python3.6/site-packages/django/db/backends/utils.py", line 77, in _execute_with_wrappers
    return executor(sql, params, many, context)
  File "/home/sravya/.local/lib/python3.6/site-packages/django/db/backends/utils.py", line 86, in _execute
    return self.cursor.execute(sql, params)
  File "/home/sravya/.local/lib/python3.6/site-packages/django/db/utils.py", line 90, in __exit__
    raise dj_exc_value.with_traceback(traceback) from exc_value
  File "/home/sravya/.local/lib/python3.6/site-packages/django/db/backends/utils.py", line 86, in _execute
    return self.cursor.execute(sql, params)
django.db.utils.ProgrammingError: column SCPapp_file.created does not exist
LINE 1: ...berofUpvotes", "SCPapp_file"."numberofDownvotes", "SCPapp_fi...
                                                             ^

2020-05-22 13:49:24,573 INFO     [views.py:135] Trying: GET: PYQ Data
2020-05-22 13:49:24,587 INFO     [views.py:152] Successful: GET: PYQ Data
2020-05-22 13:52:54,899 INFO     [views.py:135] Trying: GET: PYQ Data
2020-05-22 13:52:54,900 INFO     [views.py:152] Successful: GET: PYQ Data
2020-05-22 14:06:06,216 INFO     [autoreload.py:222] /home/sravya/SPEW/BackenedAfterIntegrationwithAWS/SCPapp/models.py changed, reloading.
2020-05-22 14:07:52,389 INFO     [autoreload.py:222] /home/sravya/SPEW/BackenedAfterIntegrationwithAWS/SCP/settings.py changed, reloading.
2020-05-22 19:38:12,584 INFO     [autoreload.py:222] /home/sravya/SPEW/BackenedAfterIntegrationwithAWS/SCPapp/models.py changed, reloading.
2020-05-22 14:56:50,990 INFO     [views.py:135] Trying: GET: PYQ Data
2020-05-22 14:56:50,991 INFO     [views.py:152] Successful: GET: PYQ Data
2020-05-22 15:01:27,744 INFO     [autoreload.py:222] /home/sravya/SPEW/BackenedAfterIntegrationwithAWS/SCPapp/models.py changed, reloading.
2020-05-22 15:02:43,984 INFO     [autoreload.py:222] /home/sravya/SPEW/BackenedAfterIntegrationwithAWS/SCPapp/models.py changed, reloading.
2020-05-22 15:03:20,66 INFO     [autoreload.py:222] /home/sravya/SPEW/BackenedAfterIntegrationwithAWS/SCPapp/models.py changed, reloading.
2020-05-22 15:37:44,601 INFO     [views.py:135] Trying: GET: PYQ Data
2020-05-22 15:37:44,615 INFO     [views.py:152] Successful: GET: PYQ Data
2020-05-22 15:38:47,598 INFO     [autoreload.py:222] /home/sravya/SPEW/BackenedAfterIntegrationwithAWS/SCPapp/models.py changed, reloading.
2020-05-22 15:38:50,621 INFO     [autoreload.py:222] /home/sravya/SPEW/BackenedAfterIntegrationwithAWS/SCPapp/models.py changed, reloading.
2020-05-22 15:38:54,796 INFO     [autoreload.py:222] /home/sravya/SPEW/BackenedAfterIntegrationwithAWS/SCPapp/models.py changed, reloading.
2020-05-22 16:06:48,413 INFO     [views.py:68] Trying: GET: Interview Exp Data
2020-05-22 16:06:48,414 INFO     [views.py:71] Successful: GET: Interview Exp Data
2020-05-22 16:07:35,660 INFO     [autoreload.py:222] /home/sravya/SPEW/BackenedAfterIntegrationwithAWS/SCPapp/models.py changed, reloading.
2020-05-22 16:12:00,306 INFO     [autoreload.py:222] /home/sravya/SPEW/BackenedAfterIntegrationwithAWS/SCP/settings.py changed, reloading.
2020-05-22 21:54:19,17 INFO     [views.py:68] Trying: GET: Interview Exp Data
2020-05-22 21:54:19,18 INFO     [views.py:71] Successful: GET: Interview Exp Data
2020-05-22 22:30:52,465 INFO     [views.py:68] Trying: GET: Interview Exp Data
2020-05-22 22:30:52,599 INFO     [views.py:71] Successful: GET: Interview Exp Data
2020-05-23 00:34:07,980 INFO     [views.py:43] Trying: GET: User data by rollNumber MT2019114
2020-05-23 00:34:08,287 INFO     [views.py:53] Successful: GET: User data by rollNumber MT2019114
2020-05-23 00:34:20,882 INFO     [views.py:68] Trying: GET: Interview Exp Data
2020-05-23 00:34:20,882 INFO     [views.py:71] Successful: GET: Interview Exp Data
2020-05-23 00:34:29,893 INFO     [views.py:68] Trying: GET: Interview Exp Data
2020-05-23 00:34:29,893 INFO     [views.py:71] Successful: GET: Interview Exp Data
2020-05-23 00:34:41,875 WARNING  [log.py:228] Forbidden: /interviewData/35/
2020-05-23 00:36:03,217 INFO     [views.py:103] Trying: PATCH: Interview Exp by id 35
2020-05-23 00:36:03,217 INFO     [views.py:90] Trying: GET: Interview Exp by id 35
2020-05-23 00:36:05,738 INFO     [views.py:109] Successful: PATCH: Interview Exp by id 35, status 201
2020-05-23 00:36:32,75 INFO     [views.py:68] Trying: GET: Interview Exp Data
2020-05-23 00:36:32,76 INFO     [views.py:71] Successful: GET: Interview Exp Data
2020-05-23 00:36:40,185 INFO     [views.py:68] Trying: GET: Interview Exp Data
2020-05-23 00:36:40,186 INFO     [views.py:71] Successful: GET: Interview Exp Data
2020-05-23 00:36:45,365 INFO     [views.py:90] Trying: GET: Interview Exp by id 35
2020-05-23 00:36:47,620 INFO     [views.py:99] Successful: GET: Interview Exp by id 35
2020-05-23 00:36:47,650 INFO     [views.py:230] Trying: GET: Comments for Interview Exp by id 35
2020-05-23 00:36:47,650 INFO     [views.py:234] Successful: GET: Comments for Interview Exp by id 35
2020-05-23 00:36:59,856 INFO     [views.py:238] Trying: POST: Comments for Interview Exp by id 35
2020-05-23 00:37:02,364 INFO     [views.py:244] Successful: POST: Comments for Interview Exp by id 35, status 201
2020-05-23 00:37:02,383 INFO     [views.py:230] Trying: GET: Comments for Interview Exp by id 35
2020-05-23 00:37:02,383 INFO     [views.py:234] Successful: GET: Comments for Interview Exp by id 35
2020-05-23 00:37:49,329 INFO     [views.py:135] Trying: GET: PYQ Data
2020-05-23 00:37:49,329 INFO     [views.py:152] Successful: GET: PYQ Data
2020-05-23 00:38:27,611 INFO     [views.py:181] Trying: POST: PYQ
2020-05-23 00:38:34,933 INFO     [views.py:185] Successful: POST: PYQ, status 201
2020-05-23 00:38:46,891 INFO     [views.py:135] Trying: GET: PYQ Data
2020-05-23 00:38:46,893 INFO     [views.py:152] Successful: GET: PYQ Data
2020-05-23 00:38:53,717 INFO     [views.py:164] Trying: PATCH: PYQ by id 18
2020-05-23 00:38:53,717 INFO     [views.py:157] Trying: GET: PYQ by id 18
2020-05-23 00:38:56,232 INFO     [views.py:170] Successful: PATCH: PYQ by id 18, status 201
2020-05-23 00:39:05,850 INFO     [views.py:135] Trying: GET: PYQ Data
2020-05-23 00:39:05,850 INFO     [views.py:152] Successful: GET: PYQ Data
2020-05-23 00:39:10,966 INFO     [views.py:135] Trying: GET: PYQ Data
2020-05-23 00:39:10,967 INFO     [views.py:152] Successful: GET: PYQ Data
2020-05-23 00:39:15,193 INFO     [views.py:157] Trying: GET: PYQ by id 18
2020-05-23 00:39:17,267 INFO     [views.py:176] Successful: GET: PYQ by id 18
2020-05-23 00:39:17,299 INFO     [views.py:208] Trying: GET: Comments for PYQ by id 18
2020-05-23 00:39:17,300 INFO     [views.py:212] Successful: GET: Comments for PYQ by id 18
2020-05-23 00:39:19,427 INFO     [views.py:164] Trying: PATCH: PYQ by id 18
2020-05-23 00:39:19,427 INFO     [views.py:157] Trying: GET: PYQ by id 18
2020-05-23 00:39:21,934 INFO     [views.py:170] Successful: PATCH: PYQ by id 18, status 201
2020-05-23 00:39:28,900 INFO     [views.py:216] Trying: POST: Comments for PYQ by id 18
2020-05-23 00:39:31,355 INFO     [views.py:222] Successful: POST: Comments for PYQ by id 18, status 201
2020-05-23 00:39:31,375 INFO     [views.py:208] Trying: GET: Comments for PYQ by id 18
2020-05-23 00:39:31,377 INFO     [views.py:212] Successful: GET: Comments for PYQ by id 18
2020-05-23 00:39:57,682 ERROR    [log.py:228] Internal Server Error: /api/students/
Traceback (most recent call last):
  File "/home/sravya/.local/lib/python3.6/site-packages/django/db/backends/utils.py", line 86, in _execute
    return self.cursor.execute(sql, params)
psycopg2.errors.UndefinedColumn: column MockSchedularApp_mockschedular.day does not exist
LINE 1: ..."name", "MockSchedularApp_mockschedular"."email", "MockSched...
                                                             ^


The above exception was the direct cause of the following exception:

Traceback (most recent call last):
  File "/home/sravya/.local/lib/python3.6/site-packages/django/core/handlers/exception.py", line 34, in inner
    response = get_response(request)
  File "/home/sravya/.local/lib/python3.6/site-packages/django/core/handlers/base.py", line 115, in _get_response
    response = self.process_exception_by_middleware(e, request)
  File "/home/sravya/.local/lib/python3.6/site-packages/django/core/handlers/base.py", line 113, in _get_response
    response = wrapped_callback(request, *callback_args, **callback_kwargs)
  File "/home/sravya/.local/lib/python3.6/site-packages/django/views/decorators/csrf.py", line 54, in wrapped_view
    return view_func(*args, **kwargs)
  File "/home/sravya/.local/lib/python3.6/site-packages/django/views/generic/base.py", line 71, in view
    return self.dispatch(request, *args, **kwargs)
  File "/usr/local/lib/python3.6/dist-packages/rest_framework/views.py", line 505, in dispatch
    response = self.handle_exception(exc)
  File "/usr/local/lib/python3.6/dist-packages/rest_framework/views.py", line 465, in handle_exception
    self.raise_uncaught_exception(exc)
  File "/usr/local/lib/python3.6/dist-packages/rest_framework/views.py", line 476, in raise_uncaught_exception
    raise exc
  File "/usr/local/lib/python3.6/dist-packages/rest_framework/views.py", line 502, in dispatch
    response = handler(request, *args, **kwargs)
  File "/usr/local/lib/python3.6/dist-packages/rest_framework/decorators.py", line 50, in handler
    return func(*args, **kwargs)
  File "/home/sravya/SPEW/BackenedAfterIntegrationwithAWS/MockSchedularApp/views.py", line 27, in students_list
    return Response(serializer.data)
  File "/usr/local/lib/python3.6/dist-packages/rest_framework/serializers.py", line 760, in data
    ret = super().data
  File "/usr/local/lib/python3.6/dist-packages/rest_framework/serializers.py", line 260, in data
    self._data = self.to_representation(self.instance)
  File "/usr/local/lib/python3.6/dist-packages/rest_framework/serializers.py", line 678, in to_representation
    self.child.to_representation(item) for item in iterable
  File "/home/sravya/.local/lib/python3.6/site-packages/django/db/models/query.py", line 276, in __iter__
    self._fetch_all()
  File "/home/sravya/.local/lib/python3.6/site-packages/django/db/models/query.py", line 1261, in _fetch_all
    self._result_cache = list(self._iterable_class(self))
  File "/home/sravya/.local/lib/python3.6/site-packages/django/db/models/query.py", line 57, in __iter__
    results = compiler.execute_sql(chunked_fetch=self.chunked_fetch, chunk_size=self.chunk_size)
  File "/home/sravya/.local/lib/python3.6/site-packages/django/db/models/sql/compiler.py", line 1151, in execute_sql
    cursor.execute(sql, params)
  File "/home/sravya/.local/lib/python3.6/site-packages/django/db/backends/utils.py", line 100, in execute
    return super().execute(sql, params)
  File "/home/sravya/.local/lib/python3.6/site-packages/django/db/backends/utils.py", line 68, in execute
    return self._execute_with_wrappers(sql, params, many=False, executor=self._execute)
  File "/home/sravya/.local/lib/python3.6/site-packages/django/db/backends/utils.py", line 77, in _execute_with_wrappers
    return executor(sql, params, many, context)
  File "/home/sravya/.local/lib/python3.6/site-packages/django/db/backends/utils.py", line 86, in _execute
    return self.cursor.execute(sql, params)
  File "/home/sravya/.local/lib/python3.6/site-packages/django/db/utils.py", line 90, in __exit__
    raise dj_exc_value.with_traceback(traceback) from exc_value
  File "/home/sravya/.local/lib/python3.6/site-packages/django/db/backends/utils.py", line 86, in _execute
    return self.cursor.execute(sql, params)
django.db.utils.ProgrammingError: column MockSchedularApp_mockschedular.day does not exist
LINE 1: ..."name", "MockSchedularApp_mockschedular"."email", "MockSched...
                                                             ^

2020-05-23 00:43:19,908 INFO     [autoreload.py:222] /home/sravya/SPEW/BackenedAfterIntegrationwithAWS/SCP/settings.py changed, reloading.
2020-05-22 19:13:35,907 INFO     [views.py:43] Trying: GET: User data by rollNumber MT2019114
2020-05-22 19:13:37,933 INFO     [views.py:53] Successful: GET: User data by rollNumber MT2019114
2020-05-22 19:15:15,225 ERROR    [log.py:228] Internal Server Error: /api/students/
Traceback (most recent call last):
  File "/home/sravya/.local/lib/python3.6/site-packages/django/db/backends/utils.py", line 86, in _execute
    return self.cursor.execute(sql, params)
psycopg2.errors.UndefinedColumn: column MockSchedularApp_mockschedular.day does not exist
LINE 1: ..."name", "MockSchedularApp_mockschedular"."email", "MockSched...
                                                             ^


The above exception was the direct cause of the following exception:

Traceback (most recent call last):
  File "/home/sravya/.local/lib/python3.6/site-packages/django/core/handlers/exception.py", line 34, in inner
    response = get_response(request)
  File "/home/sravya/.local/lib/python3.6/site-packages/django/core/handlers/base.py", line 115, in _get_response
    response = self.process_exception_by_middleware(e, request)
  File "/home/sravya/.local/lib/python3.6/site-packages/django/core/handlers/base.py", line 113, in _get_response
    response = wrapped_callback(request, *callback_args, **callback_kwargs)
  File "/home/sravya/.local/lib/python3.6/site-packages/django/views/decorators/csrf.py", line 54, in wrapped_view
    return view_func(*args, **kwargs)
  File "/home/sravya/.local/lib/python3.6/site-packages/django/views/generic/base.py", line 71, in view
    return self.dispatch(request, *args, **kwargs)
  File "/usr/local/lib/python3.6/dist-packages/rest_framework/views.py", line 505, in dispatch
    response = self.handle_exception(exc)
  File "/usr/local/lib/python3.6/dist-packages/rest_framework/views.py", line 465, in handle_exception
    self.raise_uncaught_exception(exc)
  File "/usr/local/lib/python3.6/dist-packages/rest_framework/views.py", line 476, in raise_uncaught_exception
    raise exc
  File "/usr/local/lib/python3.6/dist-packages/rest_framework/views.py", line 502, in dispatch
    response = handler(request, *args, **kwargs)
  File "/usr/local/lib/python3.6/dist-packages/rest_framework/decorators.py", line 50, in handler
    return func(*args, **kwargs)
  File "/home/sravya/SPEW/BackenedAfterIntegrationwithAWS/MockSchedularApp/views.py", line 27, in students_list
    return Response(serializer.data)
  File "/usr/local/lib/python3.6/dist-packages/rest_framework/serializers.py", line 760, in data
    ret = super().data
  File "/usr/local/lib/python3.6/dist-packages/rest_framework/serializers.py", line 260, in data
    self._data = self.to_representation(self.instance)
  File "/usr/local/lib/python3.6/dist-packages/rest_framework/serializers.py", line 678, in to_representation
    self.child.to_representation(item) for item in iterable
  File "/home/sravya/.local/lib/python3.6/site-packages/django/db/models/query.py", line 276, in __iter__
    self._fetch_all()
  File "/home/sravya/.local/lib/python3.6/site-packages/django/db/models/query.py", line 1261, in _fetch_all
    self._result_cache = list(self._iterable_class(self))
  File "/home/sravya/.local/lib/python3.6/site-packages/django/db/models/query.py", line 57, in __iter__
    results = compiler.execute_sql(chunked_fetch=self.chunked_fetch, chunk_size=self.chunk_size)
  File "/home/sravya/.local/lib/python3.6/site-packages/django/db/models/sql/compiler.py", line 1151, in execute_sql
    cursor.execute(sql, params)
  File "/home/sravya/.local/lib/python3.6/site-packages/django/db/backends/utils.py", line 100, in execute
    return super().execute(sql, params)
  File "/home/sravya/.local/lib/python3.6/site-packages/django/db/backends/utils.py", line 68, in execute
    return self._execute_with_wrappers(sql, params, many=False, executor=self._execute)
  File "/home/sravya/.local/lib/python3.6/site-packages/django/db/backends/utils.py", line 77, in _execute_with_wrappers
    return executor(sql, params, many, context)
  File "/home/sravya/.local/lib/python3.6/site-packages/django/db/backends/utils.py", line 86, in _execute
    return self.cursor.execute(sql, params)
  File "/home/sravya/.local/lib/python3.6/site-packages/django/db/utils.py", line 90, in __exit__
    raise dj_exc_value.with_traceback(traceback) from exc_value
  File "/home/sravya/.local/lib/python3.6/site-packages/django/db/backends/utils.py", line 86, in _execute
    return self.cursor.execute(sql, params)
django.db.utils.ProgrammingError: column MockSchedularApp_mockschedular.day does not exist
LINE 1: ..."name", "MockSchedularApp_mockschedular"."email", "MockSched...
                                                             ^

2020-05-22 19:19:04,420 INFO     [autoreload.py:222] /home/sravya/SPEW/BackenedAfterIntegrationwithAWS/SCP/settings.py changed, reloading.
2020-05-22 19:36:09,384 ERROR    [log.py:228] Internal Server Error: /api/students/
Traceback (most recent call last):
  File "/home/sravya/.local/lib/python3.6/site-packages/django/db/backends/utils.py", line 86, in _execute
    return self.cursor.execute(sql, params)
psycopg2.errors.UndefinedColumn: column MockSchedularApp_mockschedular.day does not exist
LINE 1: ..."name", "MockSchedularApp_mockschedular"."email", "MockSched...
                                                             ^


The above exception was the direct cause of the following exception:

Traceback (most recent call last):
  File "/home/sravya/.local/lib/python3.6/site-packages/django/core/handlers/exception.py", line 34, in inner
    response = get_response(request)
  File "/home/sravya/.local/lib/python3.6/site-packages/django/core/handlers/base.py", line 115, in _get_response
    response = self.process_exception_by_middleware(e, request)
  File "/home/sravya/.local/lib/python3.6/site-packages/django/core/handlers/base.py", line 113, in _get_response
    response = wrapped_callback(request, *callback_args, **callback_kwargs)
  File "/home/sravya/.local/lib/python3.6/site-packages/django/views/decorators/csrf.py", line 54, in wrapped_view
    return view_func(*args, **kwargs)
  File "/home/sravya/.local/lib/python3.6/site-packages/django/views/generic/base.py", line 71, in view
    return self.dispatch(request, *args, **kwargs)
  File "/usr/local/lib/python3.6/dist-packages/rest_framework/views.py", line 505, in dispatch
    response = self.handle_exception(exc)
  File "/usr/local/lib/python3.6/dist-packages/rest_framework/views.py", line 465, in handle_exception
    self.raise_uncaught_exception(exc)
  File "/usr/local/lib/python3.6/dist-packages/rest_framework/views.py", line 476, in raise_uncaught_exception
    raise exc
  File "/usr/local/lib/python3.6/dist-packages/rest_framework/views.py", line 502, in dispatch
    response = handler(request, *args, **kwargs)
  File "/usr/local/lib/python3.6/dist-packages/rest_framework/decorators.py", line 50, in handler
    return func(*args, **kwargs)
  File "/home/sravya/SPEW/BackenedAfterIntegrationwithAWS/MockSchedularApp/views.py", line 27, in students_list
    return Response(serializer.data)
  File "/usr/local/lib/python3.6/dist-packages/rest_framework/serializers.py", line 760, in data
    ret = super().data
  File "/usr/local/lib/python3.6/dist-packages/rest_framework/serializers.py", line 260, in data
    self._data = self.to_representation(self.instance)
  File "/usr/local/lib/python3.6/dist-packages/rest_framework/serializers.py", line 678, in to_representation
    self.child.to_representation(item) for item in iterable
  File "/home/sravya/.local/lib/python3.6/site-packages/django/db/models/query.py", line 276, in __iter__
    self._fetch_all()
  File "/home/sravya/.local/lib/python3.6/site-packages/django/db/models/query.py", line 1261, in _fetch_all
    self._result_cache = list(self._iterable_class(self))
  File "/home/sravya/.local/lib/python3.6/site-packages/django/db/models/query.py", line 57, in __iter__
    results = compiler.execute_sql(chunked_fetch=self.chunked_fetch, chunk_size=self.chunk_size)
  File "/home/sravya/.local/lib/python3.6/site-packages/django/db/models/sql/compiler.py", line 1151, in execute_sql
    cursor.execute(sql, params)
  File "/home/sravya/.local/lib/python3.6/site-packages/django/db/backends/utils.py", line 100, in execute
    return super().execute(sql, params)
  File "/home/sravya/.local/lib/python3.6/site-packages/django/db/backends/utils.py", line 68, in execute
    return self._execute_with_wrappers(sql, params, many=False, executor=self._execute)
  File "/home/sravya/.local/lib/python3.6/site-packages/django/db/backends/utils.py", line 77, in _execute_with_wrappers
    return executor(sql, params, many, context)
  File "/home/sravya/.local/lib/python3.6/site-packages/django/db/backends/utils.py", line 86, in _execute
    return self.cursor.execute(sql, params)
  File "/home/sravya/.local/lib/python3.6/site-packages/django/db/utils.py", line 90, in __exit__
    raise dj_exc_value.with_traceback(traceback) from exc_value
  File "/home/sravya/.local/lib/python3.6/site-packages/django/db/backends/utils.py", line 86, in _execute
    return self.cursor.execute(sql, params)
django.db.utils.ProgrammingError: column MockSchedularApp_mockschedular.day does not exist
LINE 1: ..."name", "MockSchedularApp_mockschedular"."email", "MockSched...
                                                             ^

2020-05-22 19:36:32,212 INFO     [views.py:135] Trying: GET: PYQ Data
2020-05-22 19:36:32,213 INFO     [views.py:152] Successful: GET: PYQ Data
2020-05-22 19:36:46,99 INFO     [views.py:68] Trying: GET: Interview Exp Data
2020-05-22 19:36:46,99 INFO     [views.py:71] Successful: GET: Interview Exp Data
2020-05-22 19:36:56,863 WARNING  [log.py:228] Not Found: /students/
2020-05-22 19:37:19,924 ERROR    [log.py:228] Internal Server Error: /api/students/
Traceback (most recent call last):
  File "/home/sravya/.local/lib/python3.6/site-packages/django/db/backends/utils.py", line 86, in _execute
    return self.cursor.execute(sql, params)
psycopg2.errors.UndefinedColumn: column MockSchedularApp_mockschedular.day does not exist
LINE 1: ..."name", "MockSchedularApp_mockschedular"."email", "MockSched...
                                                             ^


The above exception was the direct cause of the following exception:

Traceback (most recent call last):
  File "/home/sravya/.local/lib/python3.6/site-packages/django/core/handlers/exception.py", line 34, in inner
    response = get_response(request)
  File "/home/sravya/.local/lib/python3.6/site-packages/django/core/handlers/base.py", line 115, in _get_response
    response = self.process_exception_by_middleware(e, request)
  File "/home/sravya/.local/lib/python3.6/site-packages/django/core/handlers/base.py", line 113, in _get_response
    response = wrapped_callback(request, *callback_args, **callback_kwargs)
  File "/home/sravya/.local/lib/python3.6/site-packages/django/views/decorators/csrf.py", line 54, in wrapped_view
    return view_func(*args, **kwargs)
  File "/home/sravya/.local/lib/python3.6/site-packages/django/views/generic/base.py", line 71, in view
    return self.dispatch(request, *args, **kwargs)
  File "/usr/local/lib/python3.6/dist-packages/rest_framework/views.py", line 505, in dispatch
    response = self.handle_exception(exc)
  File "/usr/local/lib/python3.6/dist-packages/rest_framework/views.py", line 465, in handle_exception
    self.raise_uncaught_exception(exc)
  File "/usr/local/lib/python3.6/dist-packages/rest_framework/views.py", line 476, in raise_uncaught_exception
    raise exc
  File "/usr/local/lib/python3.6/dist-packages/rest_framework/views.py", line 502, in dispatch
    response = handler(request, *args, **kwargs)
  File "/usr/local/lib/python3.6/dist-packages/rest_framework/decorators.py", line 50, in handler
    return func(*args, **kwargs)
  File "/home/sravya/SPEW/BackenedAfterIntegrationwithAWS/MockSchedularApp/views.py", line 27, in students_list
    return Response(serializer.data)
  File "/usr/local/lib/python3.6/dist-packages/rest_framework/serializers.py", line 760, in data
    ret = super().data
  File "/usr/local/lib/python3.6/dist-packages/rest_framework/serializers.py", line 260, in data
    self._data = self.to_representation(self.instance)
  File "/usr/local/lib/python3.6/dist-packages/rest_framework/serializers.py", line 678, in to_representation
    self.child.to_representation(item) for item in iterable
  File "/home/sravya/.local/lib/python3.6/site-packages/django/db/models/query.py", line 276, in __iter__
    self._fetch_all()
  File "/home/sravya/.local/lib/python3.6/site-packages/django/db/models/query.py", line 1261, in _fetch_all
    self._result_cache = list(self._iterable_class(self))
  File "/home/sravya/.local/lib/python3.6/site-packages/django/db/models/query.py", line 57, in __iter__
    results = compiler.execute_sql(chunked_fetch=self.chunked_fetch, chunk_size=self.chunk_size)
  File "/home/sravya/.local/lib/python3.6/site-packages/django/db/models/sql/compiler.py", line 1151, in execute_sql
    cursor.execute(sql, params)
  File "/home/sravya/.local/lib/python3.6/site-packages/django/db/backends/utils.py", line 100, in execute
    return super().execute(sql, params)
  File "/home/sravya/.local/lib/python3.6/site-packages/django/db/backends/utils.py", line 68, in execute
    return self._execute_with_wrappers(sql, params, many=False, executor=self._execute)
  File "/home/sravya/.local/lib/python3.6/site-packages/django/db/backends/utils.py", line 77, in _execute_with_wrappers
    return executor(sql, params, many, context)
  File "/home/sravya/.local/lib/python3.6/site-packages/django/db/backends/utils.py", line 86, in _execute
    return self.cursor.execute(sql, params)
  File "/home/sravya/.local/lib/python3.6/site-packages/django/db/utils.py", line 90, in __exit__
    raise dj_exc_value.with_traceback(traceback) from exc_value
  File "/home/sravya/.local/lib/python3.6/site-packages/django/db/backends/utils.py", line 86, in _execute
    return self.cursor.execute(sql, params)
django.db.utils.ProgrammingError: column MockSchedularApp_mockschedular.day does not exist
LINE 1: ..."name", "MockSchedularApp_mockschedular"."email", "MockSched...
                                                             ^

2020-05-23 05:52:54,658 WARNING  [log.py:228] Not Found: /favicon.ico
2020-05-23 05:53:40,0 ERROR    [log.py:228] Internal Server Error: /admin/MockSchedularApp/mockschedular/
Traceback (most recent call last):
  File "/home/sravya/.local/lib/python3.6/site-packages/django/db/backends/utils.py", line 86, in _execute
    return self.cursor.execute(sql, params)
psycopg2.errors.UndefinedColumn: column MockSchedularApp_mockschedular.time does not exist
LINE 1: ..."name", "MockSchedularApp_mockschedular"."email", "MockSched...
                                                             ^
HINT:  Perhaps you meant to reference the column "MockSchedularApp_mockschedular.name".


The above exception was the direct cause of the following exception:

Traceback (most recent call last):
  File "/home/sravya/.local/lib/python3.6/site-packages/django/core/handlers/exception.py", line 34, in inner
    response = get_response(request)
  File "/home/sravya/.local/lib/python3.6/site-packages/django/core/handlers/base.py", line 115, in _get_response
    response = self.process_exception_by_middleware(e, request)
  File "/home/sravya/.local/lib/python3.6/site-packages/django/core/handlers/base.py", line 113, in _get_response
    response = wrapped_callback(request, *callback_args, **callback_kwargs)
  File "/home/sravya/.local/lib/python3.6/site-packages/django/contrib/admin/options.py", line 607, in wrapper
    return self.admin_site.admin_view(view)(*args, **kwargs)
  File "/home/sravya/.local/lib/python3.6/site-packages/django/utils/decorators.py", line 130, in _wrapped_view
    response = view_func(request, *args, **kwargs)
  File "/home/sravya/.local/lib/python3.6/site-packages/django/views/decorators/cache.py", line 44, in _wrapped_view_func
    response = view_func(request, *args, **kwargs)
  File "/home/sravya/.local/lib/python3.6/site-packages/django/contrib/admin/sites.py", line 231, in inner
    return view(request, *args, **kwargs)
  File "/home/sravya/.local/lib/python3.6/site-packages/django/utils/decorators.py", line 43, in _wrapper
    return bound_method(*args, **kwargs)
  File "/home/sravya/.local/lib/python3.6/site-packages/django/utils/decorators.py", line 130, in _wrapped_view
    response = view_func(request, *args, **kwargs)
  File "/home/sravya/.local/lib/python3.6/site-packages/django/contrib/admin/options.py", line 1796, in changelist_view
    'selection_note': _('0 of %(cnt)s selected') % {'cnt': len(cl.result_list)},
  File "/home/sravya/.local/lib/python3.6/site-packages/django/db/models/query.py", line 258, in __len__
    self._fetch_all()
  File "/home/sravya/.local/lib/python3.6/site-packages/django/db/models/query.py", line 1261, in _fetch_all
    self._result_cache = list(self._iterable_class(self))
  File "/home/sravya/.local/lib/python3.6/site-packages/django/db/models/query.py", line 57, in __iter__
    results = compiler.execute_sql(chunked_fetch=self.chunked_fetch, chunk_size=self.chunk_size)
  File "/home/sravya/.local/lib/python3.6/site-packages/django/db/models/sql/compiler.py", line 1151, in execute_sql
    cursor.execute(sql, params)
  File "/home/sravya/.local/lib/python3.6/site-packages/django/db/backends/utils.py", line 100, in execute
    return super().execute(sql, params)
  File "/home/sravya/.local/lib/python3.6/site-packages/django/db/backends/utils.py", line 68, in execute
    return self._execute_with_wrappers(sql, params, many=False, executor=self._execute)
  File "/home/sravya/.local/lib/python3.6/site-packages/django/db/backends/utils.py", line 77, in _execute_with_wrappers
    return executor(sql, params, many, context)
  File "/home/sravya/.local/lib/python3.6/site-packages/django/db/backends/utils.py", line 86, in _execute
    return self.cursor.execute(sql, params)
  File "/home/sravya/.local/lib/python3.6/site-packages/django/db/utils.py", line 90, in __exit__
    raise dj_exc_value.with_traceback(traceback) from exc_value
  File "/home/sravya/.local/lib/python3.6/site-packages/django/db/backends/utils.py", line 86, in _execute
    return self.cursor.execute(sql, params)
django.db.utils.ProgrammingError: column MockSchedularApp_mockschedular.time does not exist
LINE 1: ..."name", "MockSchedularApp_mockschedular"."email", "MockSched...
                                                             ^
HINT:  Perhaps you meant to reference the column "MockSchedularApp_mockschedular.name".

2020-05-23 05:54:29,459 INFO     [autoreload.py:222] /home/sravya/SPEW/BackenedAfterIntegrationwithAWS/MockSchedularApp/models.py changed, reloading.
2020-05-23 05:57:29,675 INFO     [autoreload.py:222] /home/sravya/SPEW/BackenedAfterIntegrationwithAWS/MockSchedularApp/models.py changed, reloading.
2020-05-23 06:02:08,193 INFO     [autoreload.py:222] /home/sravya/SPEW/BackenedAfterIntegrationwithAWS/MockSchedularApp/models.py changed, reloading.
2020-05-23 06:07:56,437 INFO     [views.py:43] Trying: GET: User data by rollNumber MT2019114
2020-05-23 06:07:58,604 INFO     [views.py:53] Successful: GET: User data by rollNumber MT2019114
2020-05-23 06:13:46,161 WARNING  [__init__.py:46] file_cache is unavailable when using oauth2client >= 4.0.0 or google-auth
Traceback (most recent call last):
  File "/home/sravya/.local/lib/python3.6/site-packages/googleapiclient/discovery_cache/__init__.py", line 36, in autodetect
    from google.appengine.api import memcache
ModuleNotFoundError: No module named 'google.appengine'

During handling of the above exception, another exception occurred:

Traceback (most recent call last):
  File "/home/sravya/.local/lib/python3.6/site-packages/googleapiclient/discovery_cache/file_cache.py", line 33, in <module>
    from oauth2client.contrib.locked_file import LockedFile
ModuleNotFoundError: No module named 'oauth2client.contrib.locked_file'

During handling of the above exception, another exception occurred:

Traceback (most recent call last):
  File "/home/sravya/.local/lib/python3.6/site-packages/googleapiclient/discovery_cache/file_cache.py", line 37, in <module>
    from oauth2client.locked_file import LockedFile
ModuleNotFoundError: No module named 'oauth2client.locked_file'

During handling of the above exception, another exception occurred:

Traceback (most recent call last):
  File "/home/sravya/.local/lib/python3.6/site-packages/googleapiclient/discovery_cache/__init__.py", line 42, in autodetect
    from . import file_cache
  File "/home/sravya/.local/lib/python3.6/site-packages/googleapiclient/discovery_cache/file_cache.py", line 41, in <module>
    "file_cache is unavailable when using oauth2client >= 4.0.0 or google-auth"
ImportError: file_cache is unavailable when using oauth2client >= 4.0.0 or google-auth
2020-05-23 06:13:47,103 INFO     [transport.py:185] Refreshing due to a 401 (attempt 1/2)
2020-05-23 06:13:47,104 INFO     [client.py:777] Refreshing access_token
2020-05-23 06:13:48,332 ERROR    [log.py:228] Internal Server Error: /api/students/sendmail/13
Traceback (most recent call last):
  File "/home/sravya/.local/lib/python3.6/site-packages/django/core/handlers/exception.py", line 34, in inner
    response = get_response(request)
  File "/home/sravya/.local/lib/python3.6/site-packages/django/core/handlers/base.py", line 115, in _get_response
    response = self.process_exception_by_middleware(e, request)
  File "/home/sravya/.local/lib/python3.6/site-packages/django/core/handlers/base.py", line 113, in _get_response
    response = wrapped_callback(request, *callback_args, **callback_kwargs)
  File "/home/sravya/.local/lib/python3.6/site-packages/django/views/decorators/csrf.py", line 54, in wrapped_view
    return view_func(*args, **kwargs)
  File "/home/sravya/.local/lib/python3.6/site-packages/django/views/generic/base.py", line 71, in view
    return self.dispatch(request, *args, **kwargs)
  File "/usr/local/lib/python3.6/dist-packages/rest_framework/views.py", line 505, in dispatch
    response = self.handle_exception(exc)
  File "/usr/local/lib/python3.6/dist-packages/rest_framework/views.py", line 465, in handle_exception
    self.raise_uncaught_exception(exc)
  File "/usr/local/lib/python3.6/dist-packages/rest_framework/views.py", line 476, in raise_uncaught_exception
    raise exc
  File "/usr/local/lib/python3.6/dist-packages/rest_framework/views.py", line 502, in dispatch
    response = handler(request, *args, **kwargs)
  File "/usr/local/lib/python3.6/dist-packages/rest_framework/decorators.py", line 50, in handler
    return func(*args, **kwargs)
  File "/home/sravya/SPEW/BackenedAfterIntegrationwithAWS/MockSchedularApp/views.py", line 89, in sendmail
    sendNotifications=True, body=EVENT).execute()
  File "/home/sravya/.local/lib/python3.6/site-packages/googleapiclient/_helpers.py", line 134, in positional_wrapper
    return wrapped(*args, **kwargs)
  File "/home/sravya/.local/lib/python3.6/site-packages/googleapiclient/http.py", line 907, in execute
    raise HttpError(resp, content, uri=self.uri)
googleapiclient.errors.HttpError: <HttpError 400 when requesting https://www.googleapis.com/calendar/v3/calendars/primary/events?sendNotifications=true&alt=json returned "The specified time range is empty.">
2020-05-23 06:21:34,198 INFO     [views.py:68] Trying: GET: Interview Exp Data
2020-05-23 06:21:34,199 INFO     [views.py:71] Successful: GET: Interview Exp Data
2020-05-23 06:21:53,267 INFO     [views.py:103] Trying: PATCH: Interview Exp by id 36
2020-05-23 06:21:53,268 INFO     [views.py:90] Trying: GET: Interview Exp by id 36
2020-05-23 06:21:55,830 INFO     [views.py:109] Successful: PATCH: Interview Exp by id 36, status 201
2020-05-23 06:22:03,79 INFO     [views.py:68] Trying: GET: Interview Exp Data
2020-05-23 06:22:03,80 INFO     [views.py:71] Successful: GET: Interview Exp Data
2020-05-23 06:22:07,148 INFO     [views.py:90] Trying: GET: Interview Exp by id 36
2020-05-23 06:22:09,449 INFO     [views.py:99] Successful: GET: Interview Exp by id 36
2020-05-23 06:22:09,493 INFO     [views.py:230] Trying: GET: Comments for Interview Exp by id 36
2020-05-23 06:22:09,495 INFO     [views.py:234] Successful: GET: Comments for Interview Exp by id 36
2020-05-23 06:22:24,742 INFO     [views.py:238] Trying: POST: Comments for Interview Exp by id 36
2020-05-23 06:22:27,266 INFO     [views.py:244] Successful: POST: Comments for Interview Exp by id 36, status 201
2020-05-23 06:22:27,305 INFO     [views.py:230] Trying: GET: Comments for Interview Exp by id 36
2020-05-23 06:22:27,305 INFO     [views.py:234] Successful: GET: Comments for Interview Exp by id 36
2020-05-23 06:23:21,644 WARNING  [__init__.py:46] file_cache is unavailable when using oauth2client >= 4.0.0 or google-auth
Traceback (most recent call last):
  File "/home/sravya/.local/lib/python3.6/site-packages/googleapiclient/discovery_cache/__init__.py", line 36, in autodetect
    from google.appengine.api import memcache
ModuleNotFoundError: No module named 'google.appengine'

During handling of the above exception, another exception occurred:

Traceback (most recent call last):
  File "/home/sravya/.local/lib/python3.6/site-packages/googleapiclient/discovery_cache/file_cache.py", line 33, in <module>
    from oauth2client.contrib.locked_file import LockedFile
ModuleNotFoundError: No module named 'oauth2client.contrib.locked_file'

During handling of the above exception, another exception occurred:

Traceback (most recent call last):
  File "/home/sravya/.local/lib/python3.6/site-packages/googleapiclient/discovery_cache/file_cache.py", line 37, in <module>
    from oauth2client.locked_file import LockedFile
ModuleNotFoundError: No module named 'oauth2client.locked_file'

During handling of the above exception, another exception occurred:

Traceback (most recent call last):
  File "/home/sravya/.local/lib/python3.6/site-packages/googleapiclient/discovery_cache/__init__.py", line 42, in autodetect
    from . import file_cache
  File "/home/sravya/.local/lib/python3.6/site-packages/googleapiclient/discovery_cache/file_cache.py", line 41, in <module>
    "file_cache is unavailable when using oauth2client >= 4.0.0 or google-auth"
ImportError: file_cache is unavailable when using oauth2client >= 4.0.0 or google-auth
2020-05-23 06:23:22,687 ERROR    [log.py:228] Internal Server Error: /api/students/sendmail/12
Traceback (most recent call last):
  File "/home/sravya/.local/lib/python3.6/site-packages/django/core/handlers/exception.py", line 34, in inner
    response = get_response(request)
  File "/home/sravya/.local/lib/python3.6/site-packages/django/core/handlers/base.py", line 115, in _get_response
    response = self.process_exception_by_middleware(e, request)
  File "/home/sravya/.local/lib/python3.6/site-packages/django/core/handlers/base.py", line 113, in _get_response
    response = wrapped_callback(request, *callback_args, **callback_kwargs)
  File "/home/sravya/.local/lib/python3.6/site-packages/django/views/decorators/csrf.py", line 54, in wrapped_view
    return view_func(*args, **kwargs)
  File "/home/sravya/.local/lib/python3.6/site-packages/django/views/generic/base.py", line 71, in view
    return self.dispatch(request, *args, **kwargs)
  File "/usr/local/lib/python3.6/dist-packages/rest_framework/views.py", line 505, in dispatch
    response = self.handle_exception(exc)
  File "/usr/local/lib/python3.6/dist-packages/rest_framework/views.py", line 465, in handle_exception
    self.raise_uncaught_exception(exc)
  File "/usr/local/lib/python3.6/dist-packages/rest_framework/views.py", line 476, in raise_uncaught_exception
    raise exc
  File "/usr/local/lib/python3.6/dist-packages/rest_framework/views.py", line 502, in dispatch
    response = handler(request, *args, **kwargs)
  File "/usr/local/lib/python3.6/dist-packages/rest_framework/decorators.py", line 50, in handler
    return func(*args, **kwargs)
  File "/home/sravya/SPEW/BackenedAfterIntegrationwithAWS/MockSchedularApp/views.py", line 89, in sendmail
    sendNotifications=True, body=EVENT).execute()
  File "/home/sravya/.local/lib/python3.6/site-packages/googleapiclient/_helpers.py", line 134, in positional_wrapper
    return wrapped(*args, **kwargs)
  File "/home/sravya/.local/lib/python3.6/site-packages/googleapiclient/http.py", line 907, in execute
    raise HttpError(resp, content, uri=self.uri)
googleapiclient.errors.HttpError: <HttpError 400 when requesting https://www.googleapis.com/calendar/v3/calendars/primary/events?sendNotifications=true&alt=json returned "The specified time range is empty.">
2020-05-23 06:27:06,606 WARNING  [__init__.py:46] file_cache is unavailable when using oauth2client >= 4.0.0 or google-auth
Traceback (most recent call last):
  File "/home/sravya/.local/lib/python3.6/site-packages/googleapiclient/discovery_cache/__init__.py", line 36, in autodetect
    from google.appengine.api import memcache
ModuleNotFoundError: No module named 'google.appengine'

During handling of the above exception, another exception occurred:

Traceback (most recent call last):
  File "/home/sravya/.local/lib/python3.6/site-packages/googleapiclient/discovery_cache/file_cache.py", line 33, in <module>
    from oauth2client.contrib.locked_file import LockedFile
ModuleNotFoundError: No module named 'oauth2client.contrib.locked_file'

During handling of the above exception, another exception occurred:

Traceback (most recent call last):
  File "/home/sravya/.local/lib/python3.6/site-packages/googleapiclient/discovery_cache/file_cache.py", line 37, in <module>
    from oauth2client.locked_file import LockedFile
ModuleNotFoundError: No module named 'oauth2client.locked_file'

During handling of the above exception, another exception occurred:

Traceback (most recent call last):
  File "/home/sravya/.local/lib/python3.6/site-packages/googleapiclient/discovery_cache/__init__.py", line 42, in autodetect
    from . import file_cache
  File "/home/sravya/.local/lib/python3.6/site-packages/googleapiclient/discovery_cache/file_cache.py", line 41, in <module>
    "file_cache is unavailable when using oauth2client >= 4.0.0 or google-auth"
ImportError: file_cache is unavailable when using oauth2client >= 4.0.0 or google-auth
2020-05-23 06:27:07,559 ERROR    [log.py:228] Internal Server Error: /api/students/sendmail/14
Traceback (most recent call last):
  File "/home/sravya/.local/lib/python3.6/site-packages/django/core/handlers/exception.py", line 34, in inner
    response = get_response(request)
  File "/home/sravya/.local/lib/python3.6/site-packages/django/core/handlers/base.py", line 115, in _get_response
    response = self.process_exception_by_middleware(e, request)
  File "/home/sravya/.local/lib/python3.6/site-packages/django/core/handlers/base.py", line 113, in _get_response
    response = wrapped_callback(request, *callback_args, **callback_kwargs)
  File "/home/sravya/.local/lib/python3.6/site-packages/django/views/decorators/csrf.py", line 54, in wrapped_view
    return view_func(*args, **kwargs)
  File "/home/sravya/.local/lib/python3.6/site-packages/django/views/generic/base.py", line 71, in view
    return self.dispatch(request, *args, **kwargs)
  File "/usr/local/lib/python3.6/dist-packages/rest_framework/views.py", line 505, in dispatch
    response = self.handle_exception(exc)
  File "/usr/local/lib/python3.6/dist-packages/rest_framework/views.py", line 465, in handle_exception
    self.raise_uncaught_exception(exc)
  File "/usr/local/lib/python3.6/dist-packages/rest_framework/views.py", line 476, in raise_uncaught_exception
    raise exc
  File "/usr/local/lib/python3.6/dist-packages/rest_framework/views.py", line 502, in dispatch
    response = handler(request, *args, **kwargs)
  File "/usr/local/lib/python3.6/dist-packages/rest_framework/decorators.py", line 50, in handler
    return func(*args, **kwargs)
  File "/home/sravya/SPEW/BackenedAfterIntegrationwithAWS/MockSchedularApp/views.py", line 89, in sendmail
    sendNotifications=True, body=EVENT).execute()
  File "/home/sravya/.local/lib/python3.6/site-packages/googleapiclient/_helpers.py", line 134, in positional_wrapper
    return wrapped(*args, **kwargs)
  File "/home/sravya/.local/lib/python3.6/site-packages/googleapiclient/http.py", line 907, in execute
    raise HttpError(resp, content, uri=self.uri)
googleapiclient.errors.HttpError: <HttpError 400 when requesting https://www.googleapis.com/calendar/v3/calendars/primary/events?sendNotifications=true&alt=json returned "The specified time range is empty.">
2020-05-23 06:44:38,1 WARNING  [__init__.py:46] file_cache is unavailable when using oauth2client >= 4.0.0 or google-auth
Traceback (most recent call last):
  File "/home/sravya/.local/lib/python3.6/site-packages/googleapiclient/discovery_cache/__init__.py", line 36, in autodetect
    from google.appengine.api import memcache
ModuleNotFoundError: No module named 'google.appengine'

During handling of the above exception, another exception occurred:

Traceback (most recent call last):
  File "/home/sravya/.local/lib/python3.6/site-packages/googleapiclient/discovery_cache/file_cache.py", line 33, in <module>
    from oauth2client.contrib.locked_file import LockedFile
ModuleNotFoundError: No module named 'oauth2client.contrib.locked_file'

During handling of the above exception, another exception occurred:

Traceback (most recent call last):
  File "/home/sravya/.local/lib/python3.6/site-packages/googleapiclient/discovery_cache/file_cache.py", line 37, in <module>
    from oauth2client.locked_file import LockedFile
ModuleNotFoundError: No module named 'oauth2client.locked_file'

During handling of the above exception, another exception occurred:

Traceback (most recent call last):
  File "/home/sravya/.local/lib/python3.6/site-packages/googleapiclient/discovery_cache/__init__.py", line 42, in autodetect
    from . import file_cache
  File "/home/sravya/.local/lib/python3.6/site-packages/googleapiclient/discovery_cache/file_cache.py", line 41, in <module>
    "file_cache is unavailable when using oauth2client >= 4.0.0 or google-auth"
ImportError: file_cache is unavailable when using oauth2client >= 4.0.0 or google-auth
2020-05-23 06:46:11,419 INFO     [autoreload.py:222] /home/sravya/SPEW/BackenedAfterIntegrationwithAWS/MockSchedularApp/views.py changed, reloading.
2020-05-23 06:47:28,883 INFO     [views.py:135] Trying: GET: PYQ Data
2020-05-23 06:47:28,884 INFO     [views.py:152] Successful: GET: PYQ Data
2020-05-23 06:47:55,528 INFO     [views.py:181] Trying: POST: PYQ
2020-05-23 06:48:04,377 INFO     [views.py:185] Successful: POST: PYQ, status 201
2020-05-23 06:48:18,120 INFO     [views.py:135] Trying: GET: PYQ Data
2020-05-23 06:48:18,120 INFO     [views.py:152] Successful: GET: PYQ Data
2020-05-23 06:48:23,251 INFO     [views.py:135] Trying: GET: PYQ Data
2020-05-23 06:48:23,251 INFO     [views.py:152] Successful: GET: PYQ Data
2020-05-23 06:48:27,708 INFO     [views.py:164] Trying: PATCH: PYQ by id 19
2020-05-23 06:48:27,708 INFO     [views.py:157] Trying: GET: PYQ by id 19
2020-05-23 06:48:30,263 INFO     [views.py:170] Successful: PATCH: PYQ by id 19, status 201
2020-05-23 06:48:35,310 INFO     [views.py:135] Trying: GET: PYQ Data
2020-05-23 06:48:35,311 INFO     [views.py:152] Successful: GET: PYQ Data
2020-05-23 06:48:39,684 INFO     [views.py:157] Trying: GET: PYQ by id 19
2020-05-23 06:48:42,163 INFO     [views.py:176] Successful: GET: PYQ by id 19
2020-05-23 06:48:42,228 INFO     [views.py:208] Trying: GET: Comments for PYQ by id 19
2020-05-23 06:48:42,231 INFO     [views.py:212] Successful: GET: Comments for PYQ by id 19
2020-05-23 06:48:46,106 INFO     [views.py:164] Trying: PATCH: PYQ by id 19
2020-05-23 06:48:46,107 INFO     [views.py:157] Trying: GET: PYQ by id 19
2020-05-23 06:48:48,716 INFO     [views.py:170] Successful: PATCH: PYQ by id 19, status 201
2020-05-23 06:48:58,440 INFO     [views.py:216] Trying: POST: Comments for PYQ by id 19
2020-05-23 06:49:00,987 INFO     [views.py:222] Successful: POST: Comments for PYQ by id 19, status 201
2020-05-23 06:49:01,0 INFO     [views.py:208] Trying: GET: Comments for PYQ by id 19
2020-05-23 06:49:01,1 INFO     [views.py:212] Successful: GET: Comments for PYQ by id 19
